DEBUG 2018-07-19 10:00:15,316: 	 Executing command: 'submit'
DEBUG 2018-07-19 10:00:15,316: 	 Found CRAB cache file /uscms/home/mlu/.crab3
DEBUG 2018-07-19 10:00:15,371: 	 Checking credentials
DEBUG 2018-07-19 10:00:15,371: 	 Proxy file /tmp/x509up_u52213 not found
DEBUG 2018-07-19 10:00:15,372: 	 Creating new proxy for 24:00 hours with VO group '' and VO role 'NULL'.
DEBUG 2018-07-19 10:00:19,884: 	 Executing : 
 command : voms-proxy-init -voms cms:/cms -valid 24:00 -rfc
 output : None
 error: None
 retcode : 3
DEBUG 2018-07-19 10:00:19,989: 	 Executing : 
 command : voms-proxy-info -file /tmp/x509up_u52213 -timeleft
 output : 
 error: 
Couldn't find a valid proxy.


 retcode : 1
ERROR 2018-07-19 10:00:19,990: 	 Error while checking proxy timeleft for /tmp/x509up_u52213
DEBUG 2018-07-19 10:00:20,093: 	 Executing : 
 command : env X509_USER_PROXY=/tmp/x509up_u52213 voms-proxy-info -fqan
 output : 
 error: 
Couldn't find a valid proxy.


 retcode : 1
ERROR 2018-07-19 10:00:20,094: 	 Problems creating proxy.
ERROR 2018-07-19 10:00:20,094: 	 Caught exception
Traceback (most recent call last):
  File "/cvmfs/cms.cern.ch/crab3/slc6_amd64_gcc493/cms/crabclient/3.3.1805.patch1/bin/crab", line 160, in <module>
    client()
  File "/cvmfs/cms.cern.ch/crab3/slc6_amd64_gcc493/cms/crabclient/3.3.1805.patch1/bin/crab", line 146, in __call__
    self.cmd = sub_cmd(self.logger, args[1:])
  File "/cvmfs/cms.cern.ch/crab3/slc6_amd64_gcc493/cms/crabclient/3.3.1805.patch1/lib/python2.7/site-packages/CRABClient/Commands/submit.py", line 34, in __init__
    SubCommand.__init__(self, logger, cmdargs, disable_interspersed_args=True)
  File "/cvmfs/cms.cern.ch/crab3/slc6_amd64_gcc493/cms/crabclient/3.3.1805.patch1/lib/python2.7/site-packages/CRABClient/Commands/SubCommand.py", line 297, in __init__
    self.proxyCreated = self.proxy.createNewVomsProxySimple(timeLeftThreshold = 720)
  File "/cvmfs/cms.cern.ch/crab3/slc6_amd64_gcc493/cms/crabclient/3.3.1805.patch1/lib/python2.7/site-packages/CRABClient/CredentialInteractions.py", line 152, in createNewVomsProxySimple
    raise ProxyCreationException("Problems creating proxy.")
ProxyCreationException: Problems creating proxy.
DEBUG 2018-07-19 10:00:22,746: 	 Executing command: 'submit'
DEBUG 2018-07-19 10:00:22,746: 	 Found CRAB cache file /uscms/home/mlu/.crab3
DEBUG 2018-07-19 10:00:22,753: 	 Checking credentials
DEBUG 2018-07-19 10:00:22,754: 	 Proxy file /tmp/x509up_u52213 not found
DEBUG 2018-07-19 10:00:22,754: 	 Creating new proxy for 24:00 hours with VO group '' and VO role 'NULL'.
DEBUG 2018-07-19 10:00:26,464: 	 Executing : 
 command : voms-proxy-init -voms cms:/cms -valid 24:00 -rfc
 output : None
 error: None
 retcode : 3
DEBUG 2018-07-19 10:00:26,568: 	 Executing : 
 command : voms-proxy-info -file /tmp/x509up_u52213 -timeleft
 output : 
 error: 
Couldn't find a valid proxy.


 retcode : 1
ERROR 2018-07-19 10:00:26,569: 	 Error while checking proxy timeleft for /tmp/x509up_u52213
DEBUG 2018-07-19 10:00:26,672: 	 Executing : 
 command : env X509_USER_PROXY=/tmp/x509up_u52213 voms-proxy-info -fqan
 output : 
 error: 
Couldn't find a valid proxy.


 retcode : 1
ERROR 2018-07-19 10:00:26,672: 	 Problems creating proxy.
ERROR 2018-07-19 10:00:26,673: 	 Caught exception
Traceback (most recent call last):
  File "/cvmfs/cms.cern.ch/crab3/slc6_amd64_gcc493/cms/crabclient/3.3.1805.patch1/bin/crab", line 160, in <module>
    client()
  File "/cvmfs/cms.cern.ch/crab3/slc6_amd64_gcc493/cms/crabclient/3.3.1805.patch1/bin/crab", line 146, in __call__
    self.cmd = sub_cmd(self.logger, args[1:])
  File "/cvmfs/cms.cern.ch/crab3/slc6_amd64_gcc493/cms/crabclient/3.3.1805.patch1/lib/python2.7/site-packages/CRABClient/Commands/submit.py", line 34, in __init__
    SubCommand.__init__(self, logger, cmdargs, disable_interspersed_args=True)
  File "/cvmfs/cms.cern.ch/crab3/slc6_amd64_gcc493/cms/crabclient/3.3.1805.patch1/lib/python2.7/site-packages/CRABClient/Commands/SubCommand.py", line 297, in __init__
    self.proxyCreated = self.proxy.createNewVomsProxySimple(timeLeftThreshold = 720)
  File "/cvmfs/cms.cern.ch/crab3/slc6_amd64_gcc493/cms/crabclient/3.3.1805.patch1/lib/python2.7/site-packages/CRABClient/CredentialInteractions.py", line 152, in createNewVomsProxySimple
    raise ProxyCreationException("Problems creating proxy.")
ProxyCreationException: Problems creating proxy.
DEBUG 2018-07-19 10:00:32,873: 	 Executing command: 'submit'
DEBUG 2018-07-19 10:00:32,873: 	 Found CRAB cache file /uscms/home/mlu/.crab3
DEBUG 2018-07-19 10:00:32,880: 	 Checking credentials
DEBUG 2018-07-19 10:00:32,880: 	 Proxy file /tmp/x509up_u52213 not found
DEBUG 2018-07-19 10:00:32,880: 	 Creating new proxy for 24:00 hours with VO group '' and VO role 'NULL'.
DEBUG 2018-07-19 10:00:35,889: 	 Executing : 
 command : voms-proxy-init -voms cms:/cms -valid 24:00 -rfc
 output : None
 error: None
 retcode : 3
DEBUG 2018-07-19 10:00:35,993: 	 Executing : 
 command : voms-proxy-info -file /tmp/x509up_u52213 -timeleft
 output : 
 error: 
Couldn't find a valid proxy.


 retcode : 1
ERROR 2018-07-19 10:00:35,994: 	 Error while checking proxy timeleft for /tmp/x509up_u52213
DEBUG 2018-07-19 10:00:36,097: 	 Executing : 
 command : env X509_USER_PROXY=/tmp/x509up_u52213 voms-proxy-info -fqan
 output : 
 error: 
Couldn't find a valid proxy.


 retcode : 1
ERROR 2018-07-19 10:00:36,098: 	 Problems creating proxy.
ERROR 2018-07-19 10:00:36,098: 	 Caught exception
Traceback (most recent call last):
  File "/cvmfs/cms.cern.ch/crab3/slc6_amd64_gcc493/cms/crabclient/3.3.1805.patch1/bin/crab", line 160, in <module>
    client()
  File "/cvmfs/cms.cern.ch/crab3/slc6_amd64_gcc493/cms/crabclient/3.3.1805.patch1/bin/crab", line 146, in __call__
    self.cmd = sub_cmd(self.logger, args[1:])
  File "/cvmfs/cms.cern.ch/crab3/slc6_amd64_gcc493/cms/crabclient/3.3.1805.patch1/lib/python2.7/site-packages/CRABClient/Commands/submit.py", line 34, in __init__
    SubCommand.__init__(self, logger, cmdargs, disable_interspersed_args=True)
  File "/cvmfs/cms.cern.ch/crab3/slc6_amd64_gcc493/cms/crabclient/3.3.1805.patch1/lib/python2.7/site-packages/CRABClient/Commands/SubCommand.py", line 297, in __init__
    self.proxyCreated = self.proxy.createNewVomsProxySimple(timeLeftThreshold = 720)
  File "/cvmfs/cms.cern.ch/crab3/slc6_amd64_gcc493/cms/crabclient/3.3.1805.patch1/lib/python2.7/site-packages/CRABClient/CredentialInteractions.py", line 152, in createNewVomsProxySimple
    raise ProxyCreationException("Problems creating proxy.")
ProxyCreationException: Problems creating proxy.
DEBUG 2018-07-19 10:00:37,821: 	 Executing command: 'submit'
DEBUG 2018-07-19 10:00:37,821: 	 Found CRAB cache file /uscms/home/mlu/.crab3
DEBUG 2018-07-19 10:00:37,828: 	 Checking credentials
DEBUG 2018-07-19 10:00:37,829: 	 Proxy file /tmp/x509up_u52213 not found
DEBUG 2018-07-19 10:00:37,829: 	 Creating new proxy for 24:00 hours with VO group '' and VO role 'NULL'.
DEBUG 2018-07-19 10:00:40,637: 	 Executing : 
 command : voms-proxy-init -voms cms:/cms -valid 24:00 -rfc
 output : None
 error: None
 retcode : 3
DEBUG 2018-07-19 10:00:40,741: 	 Executing : 
 command : voms-proxy-info -file /tmp/x509up_u52213 -timeleft
 output : 
 error: 
Couldn't find a valid proxy.


 retcode : 1
ERROR 2018-07-19 10:00:40,742: 	 Error while checking proxy timeleft for /tmp/x509up_u52213
DEBUG 2018-07-19 10:00:40,845: 	 Executing : 
 command : env X509_USER_PROXY=/tmp/x509up_u52213 voms-proxy-info -fqan
 output : 
 error: 
Couldn't find a valid proxy.


 retcode : 1
ERROR 2018-07-19 10:00:40,846: 	 Problems creating proxy.
ERROR 2018-07-19 10:00:40,846: 	 Caught exception
Traceback (most recent call last):
  File "/cvmfs/cms.cern.ch/crab3/slc6_amd64_gcc493/cms/crabclient/3.3.1805.patch1/bin/crab", line 160, in <module>
    client()
  File "/cvmfs/cms.cern.ch/crab3/slc6_amd64_gcc493/cms/crabclient/3.3.1805.patch1/bin/crab", line 146, in __call__
    self.cmd = sub_cmd(self.logger, args[1:])
  File "/cvmfs/cms.cern.ch/crab3/slc6_amd64_gcc493/cms/crabclient/3.3.1805.patch1/lib/python2.7/site-packages/CRABClient/Commands/submit.py", line 34, in __init__
    SubCommand.__init__(self, logger, cmdargs, disable_interspersed_args=True)
  File "/cvmfs/cms.cern.ch/crab3/slc6_amd64_gcc493/cms/crabclient/3.3.1805.patch1/lib/python2.7/site-packages/CRABClient/Commands/SubCommand.py", line 297, in __init__
    self.proxyCreated = self.proxy.createNewVomsProxySimple(timeLeftThreshold = 720)
  File "/cvmfs/cms.cern.ch/crab3/slc6_amd64_gcc493/cms/crabclient/3.3.1805.patch1/lib/python2.7/site-packages/CRABClient/CredentialInteractions.py", line 152, in createNewVomsProxySimple
    raise ProxyCreationException("Problems creating proxy.")
ProxyCreationException: Problems creating proxy.
DEBUG 2018-07-19 10:01:05,877: 	 Executing command: 'submit'
DEBUG 2018-07-19 10:01:05,877: 	 Found CRAB cache file /uscms/home/mlu/.crab3
DEBUG 2018-07-19 10:01:05,884: 	 Checking credentials
DEBUG 2018-07-19 10:01:05,884: 	 Proxy file /tmp/x509up_u52213 not found
DEBUG 2018-07-19 10:01:05,885: 	 Creating new proxy for 24:00 hours with VO group '' and VO role 'NULL'.
DEBUG 2018-07-19 10:01:09,395: 	 Executing : 
 command : voms-proxy-init -voms cms:/cms -valid 24:00 -rfc
 output : None
 error: None
 retcode : 0
DEBUG 2018-07-19 10:01:09,499: 	 Executing : 
 command : voms-proxy-info -file /tmp/x509up_u52213 -timeleft
 output : 86400

 error: 
 retcode : 0
DEBUG 2018-07-19 10:01:09,603: 	 Executing : 
 command : voms-proxy-info -file /tmp/x509up_u52213 -actimeleft
 output : 86400

 error: 
 retcode : 0
DEBUG 2018-07-19 10:01:09,706: 	 Executing : 
 command : env X509_USER_PROXY=/tmp/x509up_u52213 voms-proxy-info -fqan
 output : /cms/Role=NULL/Capability=NULL

 error: 
 retcode : 0
DEBUG 2018-07-19 10:01:09,707: 	 Proxy created.
INFO 2018-07-19 10:01:09,707: 	 Will use CRAB configuration file Zcrab/crab3_analysisZA_jec_sig.py
DEBUG 2018-07-19 10:01:09,708: 	 Loading CRAB configuration file.
DEBUG 2018-07-19 10:01:09,742: 	 Will use CRAB Analysis plugin (i.e. will run an analysis job type).
ERROR 2018-07-19 10:01:09,743: 	 Working area '/uscms_data/d3/mlu/CMSSW_8_0_26_patch2/src/VAJets/PKUTreeMaker/test/crab_Z-ZA-EWK-1' already exists 
Please change the requestName in the config file
ERROR 2018-07-19 10:01:09,743: 	 Caught exception
Traceback (most recent call last):
  File "/cvmfs/cms.cern.ch/crab3/slc6_amd64_gcc493/cms/crabclient/3.3.1805.patch1/bin/crab", line 160, in <module>
    client()
  File "/cvmfs/cms.cern.ch/crab3/slc6_amd64_gcc493/cms/crabclient/3.3.1805.patch1/bin/crab", line 146, in __call__
    self.cmd = sub_cmd(self.logger, args[1:])
  File "/cvmfs/cms.cern.ch/crab3/slc6_amd64_gcc493/cms/crabclient/3.3.1805.patch1/lib/python2.7/site-packages/CRABClient/Commands/submit.py", line 34, in __init__
    SubCommand.__init__(self, logger, cmdargs, disable_interspersed_args=True)
  File "/cvmfs/cms.cern.ch/crab3/slc6_amd64_gcc493/cms/crabclient/3.3.1805.patch1/lib/python2.7/site-packages/CRABClient/Commands/SubCommand.py", line 307, in __init__
    getattr(self.configuration.General, 'requestName', None))
  File "/cvmfs/cms.cern.ch/crab3/slc6_amd64_gcc493/cms/crabclient/3.3.1805.patch1/lib/python2.7/site-packages/CRABClient/ClientUtilities.py", line 404, in createWorkArea
    raise ConfigException("Working area '%s' already exists \nPlease change the requestName in the config file" % fullpath)
ConfigException: Working area '/uscms_data/d3/mlu/CMSSW_8_0_26_patch2/src/VAJets/PKUTreeMaker/test/crab_Z-ZA-EWK-1' already exists 
Please change the requestName in the config file
